INFO:     Will watch for changes in these directories: ['/home/workspace']
INFO:     Uvicorn running on http://0.0.0.0:8000 (Press CTRL+C to quit)
INFO:     Started reloader process [206] using StatReload
INFO:     Started server process [208]
INFO:     Waiting for application startup.
INFO:     Application startup complete.
INFO:     172.20.0.1:54420 - "HEAD / HTTP/1.1" 405 Method Not Allowed
INFO:     172.20.0.1:54390 - "POST /api/seed HTTP/1.1" 500 Internal Server Error
ERROR:    Exception in ASGI application
Traceback (most recent call last):
  File "/usr/local/lib/python3.13/site-packages/uvicorn/protocols/http/h11_impl.py", line 408, in run_asgi
    result = await app(  # type: ignore[func-returns-value]
             ^^^^^^^^^^^^^^^^^^^^^^^^^^^^^^^^^^^^^^^^^^^^^^
        self.scope, self.receive, self.send
        ^^^^^^^^^^^^^^^^^^^^^^^^^^^^^^^^^^^
    )
    ^
  File "/usr/local/lib/python3.13/site-packages/uvicorn/middleware/proxy_headers.py", line 84, in __call__
    return await self.app(scope, receive, send)
           ^^^^^^^^^^^^^^^^^^^^^^^^^^^^^^^^^^^^
  File "/usr/local/lib/python3.13/site-packages/fastapi/applications.py", line 1106, in __call__
    await super().__call__(scope, receive, send)
  File "/usr/local/lib/python3.13/site-packages/starlette/applications.py", line 122, in __call__
    await self.middleware_stack(scope, receive, send)
  File "/usr/local/lib/python3.13/site-packages/starlette/middleware/errors.py", line 184, in __call__
    raise exc
  File "/usr/local/lib/python3.13/site-packages/starlette/middleware/errors.py", line 162, in __call__
    await self.app(scope, receive, _send)
  File "/usr/local/lib/python3.13/site-packages/starlette/middleware/cors.py", line 91, in __call__
    await self.simple_response(scope, receive, send, request_headers=headers)
  File "/usr/local/lib/python3.13/site-packages/starlette/middleware/cors.py", line 146, in simple_response
    await self.app(scope, receive, send)
  File "/usr/local/lib/python3.13/site-packages/starlette/middleware/exceptions.py", line 79, in __call__
    raise exc
  File "/usr/local/lib/python3.13/site-packages/starlette/middleware/exceptions.py", line 68, in __call__
    await self.app(scope, receive, sender)
  File "/usr/local/lib/python3.13/site-packages/fastapi/middleware/asyncexitstack.py", line 20, in __call__
    raise e
  File "/usr/local/lib/python3.13/site-packages/fastapi/middleware/asyncexitstack.py", line 17, in __call__
    await self.app(scope, receive, send)
  File "/usr/local/lib/python3.13/site-packages/starlette/routing.py", line 718, in __call__
    await route.handle(scope, receive, send)
  File "/usr/local/lib/python3.13/site-packages/starlette/routing.py", line 276, in handle
    await self.app(scope, receive, send)
  File "/usr/local/lib/python3.13/site-packages/starlette/routing.py", line 66, in app
    response = await func(request)
               ^^^^^^^^^^^^^^^^^^^
  File "/usr/local/lib/python3.13/site-packages/fastapi/routing.py", line 274, in app
    raw_response = await run_endpoint_function(
                   ^^^^^^^^^^^^^^^^^^^^^^^^^^^^
        dependant=dependant, values=values, is_coroutine=is_coroutine
        ^^^^^^^^^^^^^^^^^^^^^^^^^^^^^^^^^^^^^^^^^^^^^^^^^^^^^^^^^^^^^
    )
    ^
  File "/usr/local/lib/python3.13/site-packages/fastapi/routing.py", line 193, in run_endpoint_function
    return await run_in_threadpool(dependant.call, **values)
           ^^^^^^^^^^^^^^^^^^^^^^^^^^^^^^^^^^^^^^^^^^^^^^^^^
  File "/usr/local/lib/python3.13/site-packages/starlette/concurrency.py", line 41, in run_in_threadpool
    return await anyio.to_thread.run_sync(func, *args)
           ^^^^^^^^^^^^^^^^^^^^^^^^^^^^^^^^^^^^^^^^^^^
  File "/usr/local/lib/python3.13/site-packages/anyio/to_thread.py", line 33, in run_sync
    return await get_asynclib().run_sync_in_worker_thread(
           ^^^^^^^^^^^^^^^^^^^^^^^^^^^^^^^^^^^^^^^^^^^^^^^
        func, *args, cancellable=cancellable, limiter=limiter
        ^^^^^^^^^^^^^^^^^^^^^^^^^^^^^^^^^^^^^^^^^^^^^^^^^^^^^
    )
    ^
  File "/usr/local/lib/python3.13/site-packages/anyio/_backends/_asyncio.py", line 877, in run_sync_in_worker_thread
    return await future
           ^^^^^^^^^^^^
  File "/usr/local/lib/python3.13/site-packages/anyio/_backends/_asyncio.py", line 807, in run
    result = context.run(func, *args)
  File "/home/workspace/main.py", line 76, in seed
    ngo_ids.append(db["ngo"].insert_one(NGO(name="Aranya Eco Foundation", registration_id="KA-REG-001", category="Air", city="Bengaluru", state="Karnataka", verified=True).model_dump()).inserted_id)
                   ~~~~~~~~~~~~~~~~~~~~^^^^^^^^^^^^^^^^^^^^^^^^^^^^^^^^^^^^^^^^^^^^^^^^^^^^^^^^^^^^^^^^^^^^^^^^^^^^^^^^^^^^^^^^^^^^^^^^^^^^^^^^^^^^^^^^^^^^^^^^^^^^^^^^^^^^^^^^^^^^^^^^^^
  File "/usr/local/lib/python3.13/site-packages/pymongo/collection.py", line 669, in insert_one
    self._insert_one(
    ~~~~~~~~~~~~~~~~^
        document,
        ^^^^^^^^^
    ...<5 lines>...
        comment=comment,
        ^^^^^^^^^^^^^^^^
    ),
    ^
  File "/usr/local/lib/python3.13/site-packages/pymongo/collection.py", line 609, in _insert_one
    self.__database.client._retryable_write(acknowledged, _insert_command, session)
    ~~~~~~~~~~~~~~~~~~~~~~~~~~~~~~~~~~~~~~~^^^^^^^^^^^^^^^^^^^^^^^^^^^^^^^^^^^^^^^^
  File "/usr/local/lib/python3.13/site-packages/pymongo/mongo_client.py", line 1523, in _retryable_write
    return self._retry_with_session(retryable, func, s, bulk)
           ~~~~~~~~~~~~~~~~~~~~~~~~^^^^^^^^^^^^^^^^^^^^^^^^^^
  File "/usr/local/lib/python3.13/site-packages/pymongo/mongo_client.py", line 1421, in _retry_with_session
    return self._retry_internal(
           ~~~~~~~~~~~~~~~~~~~~^
        func=func,
        ^^^^^^^^^^
    ...<2 lines>...
        retryable=retryable,
        ^^^^^^^^^^^^^^^^^^^^
    )
    ^
  File "/usr/local/lib/python3.13/site-packages/pymongo/_csot.py", line 107, in csot_wrapper
    return func(self, *args, **kwargs)
  File "/usr/local/lib/python3.13/site-packages/pymongo/mongo_client.py", line 1462, in _retry_internal
    ).run()
      ~~~^^
  File "/usr/local/lib/python3.13/site-packages/pymongo/mongo_client.py", line 2315, in run
    return self._read() if self._is_read else self._write()
                                              ~~~~~~~~~~~^^
  File "/usr/local/lib/python3.13/site-packages/pymongo/mongo_client.py", line 2422, in _write
    return self._func(self._session, conn, self._retryable)  # type: ignore
           ~~~~~~~~~~^^^^^^^^^^^^^^^^^^^^^^^^^^^^^^^^^^^^^^
  File "/usr/local/lib/python3.13/site-packages/pymongo/collection.py", line 597, in _insert_command
    result = conn.command(
        self.__database.name,
    ...<5 lines>...
        retryable_write=retryable_write,
    )
  File "/usr/local/lib/python3.13/site-packages/pymongo/helpers.py", line 322, in inner
    return func(*args, **kwargs)
  File "/usr/local/lib/python3.13/site-packages/pymongo/pool.py", line 968, in command
    return command(
        self,
    ...<20 lines>...
        write_concern=write_concern,
    )
  File "/usr/local/lib/python3.13/site-packages/pymongo/network.py", line 192, in command
    helpers._check_command_response(
    ~~~~~~~~~~~~~~~~~~~~~~~~~~~~~~~^
        response_doc,
        ^^^^^^^^^^^^^
    ...<2 lines>...
        parse_write_concern_error=parse_write_concern_error,
        ^^^^^^^^^^^^^^^^^^^^^^^^^^^^^^^^^^^^^^^^^^^^^^^^^^^^
    )
    ^
  File "/usr/local/lib/python3.13/site-packages/pymongo/helpers.py", line 230, in _check_command_response
    raise OperationFailure(errmsg, code, response, max_wire_version)
pymongo.errors.OperationFailure: Error=13, Details='Response status code does not indicate success: Forbidden (403); Substatus: 3090; ActivityId: 6d87d335-6090-4d63-98f5-13aca7dbf1ad; Reason: ({"code":"Forbidden","message":"Message: {\"Errors\":[\"Database / Collection Count Quota exceeded: Maximum number of 'Collection' per account exceeded. Current configured quota 500. Learn more https://aka.ms/cosmosdbquota\"]}\r\nActivityId: 6d87d335-6090-4d63-98f5-13aca7dbf1ad, Request URI: /apps/fc754a62-8507-4892-949e-99f2106b4b43/services/80fca9d2-512e-449c-bc04-bdeb0dc25d79/partitions/636e5357-71c4-4640-827f-1029b8907e57/replicas/133983777128881666p, RequestStats: , SDK: Microsoft.Azure.Documents.Common/2.14.0"}
RequestUri: https://developer-platform-user-db-5-uksouth.documents.azure.com/dbs/project_prj_qc0lcs45/colls;
RequestMethod: POST;
Header: Authorization Length: 84;
Header: x-ms-date Length: 29;
Header: x-ms-cosmos-sdk-supportedcapabilities Length: 1;
Header: x-ms-cosmos-insert-systempartitionkey Length: 4;
Header: x-ms-activity-id Length: 36;
Header: Cache-Control Length: 8;
Header: User-Agent Length: 145;
Header: x-ms-cosmos-apitype Length: 7;
Header: x-ms-version Length: 10;
Header: Accept Length: 16;
Header: x-ms-cosmos-compute-hop-count Length: 1;
Header: x-ms-gateway-use-mtls Length: 1;
Header: traceparent Length: 55;
Header: tracestate Length: 6;
, Request URI: /dbs/project_prj_qc0lcs45/colls, RequestStats: Microsoft.Azure.Cosmos.Tracing.TraceData.ClientSideRequestStatisticsTraceDatum, SDK: Windows/10.0.20348 cosmos-netstandard-sdk/3.18.0);, full error: {'ok': 0.0, 'errmsg': 'Error=13, Details=\'Response status code does not indicate success: Forbidden (403); Substatus: 3090; ActivityId: 6d87d335-6090-4d63-98f5-13aca7dbf1ad; Reason: ({"code":"Forbidden","message":"Message: {\\"Errors\\":[\\"Database / Collection Count Quota exceeded: Maximum number of \'Collection\' per account exceeded. Current configured quota 500. Learn more https://aka.ms/cosmosdbquota\\"]}\\r\\nActivityId: 6d87d335-6090-4d63-98f5-13aca7dbf1ad, Request URI: /apps/fc754a62-8507-4892-949e-99f2106b4b43/services/80fca9d2-512e-449c-bc04-bdeb0dc25d79/partitions/636e5357-71c4-4640-827f-1029b8907e57/replicas/133983777128881666p, RequestStats: , SDK: Microsoft.Azure.Documents.Common/2.14.0"}\r\nRequestUri: https://developer-platform-user-db-5-uksouth.documents.azure.com/dbs/project_prj_qc0lcs45/colls;\r\nRequestMethod: POST;\r\nHeader: Authorization Length: 84;\r\nHeader: x-ms-date Length: 29;\r\nHeader: x-ms-cosmos-sdk-supportedcapabilities Length: 1;\r\nHeader: x-ms-cosmos-insert-systempartitionkey Length: 4;\r\nHeader: x-ms-activity-id Length: 36;\r\nHeader: Cache-Control Length: 8;\r\nHeader: User-Agent Length: 145;\r\nHeader: x-ms-cosmos-apitype Length: 7;\r\nHeader: x-ms-version Length: 10;\r\nHeader: Accept Length: 16;\r\nHeader: x-ms-cosmos-compute-hop-count Length: 1;\r\nHeader: x-ms-gateway-use-mtls Length: 1;\r\nHeader: traceparent Length: 55;\r\nHeader: tracestate Length: 6;\r\n, Request URI: /dbs/project_prj_qc0lcs45/colls, RequestStats: Microsoft.Azure.Cosmos.Tracing.TraceData.ClientSideRequestStatisticsTraceDatum, SDK: Windows/10.0.20348 cosmos-netstandard-sdk/3.18.0);', 'code': 13, 'codeName': 'Unauthorized'}
INFO:     172.20.0.1:54378 - "GET /api/transactions HTTP/1.1" 200 OK
INFO:     172.20.0.1:54392 - "GET /api/campaigns HTTP/1.1" 200 OK
INFO:     172.20.0.1:54406 - "POST /api/seed HTTP/1.1" 500 Internal Server Error
ERROR:    Exception in ASGI application
Traceback (most recent call last):
  File "/usr/local/lib/python3.13/site-packages/uvicorn/protocols/http/h11_impl.py", line 408, in run_asgi
    result = await app(  # type: ignore[func-returns-value]
             ^^^^^^^^^^^^^^^^^^^^^^^^^^^^^^^^^^^^^^^^^^^^^^
        self.scope, self.receive, self.send
        ^^^^^^^^^^^^^^^^^^^^^^^^^^^^^^^^^^^
    )
    ^
  File "/usr/local/lib/python3.13/site-packages/uvicorn/middleware/proxy_headers.py", line 84, in __call__
    return await self.app(scope, receive, send)
           ^^^^^^^^^^^^^^^^^^^^^^^^^^^^^^^^^^^^
  File "/usr/local/lib/python3.13/site-packages/fastapi/applications.py", line 1106, in __call__
    await super().__call__(scope, receive, send)
  File "/usr/local/lib/python3.13/site-packages/starlette/applications.py", line 122, in __call__
    await self.middleware_stack(scope, receive, send)
  File "/usr/local/lib/python3.13/site-packages/starlette/middleware/errors.py", line 184, in __call__
    raise exc
  File "/usr/local/lib/python3.13/site-packages/starlette/middleware/errors.py", line 162, in __call__
    await self.app(scope, receive, _send)
  File "/usr/local/lib/python3.13/site-packages/starlette/middleware/cors.py", line 91, in __call__
    await self.simple_response(scope, receive, send, request_headers=headers)
  File "/usr/local/lib/python3.13/site-packages/starlette/middleware/cors.py", line 146, in simple_response
    await self.app(scope, receive, send)
  File "/usr/local/lib/python3.13/site-packages/starlette/middleware/exceptions.py", line 79, in __call__
    raise exc
  File "/usr/local/lib/python3.13/site-packages/starlette/middleware/exceptions.py", line 68, in __call__
    await self.app(scope, receive, sender)
  File "/usr/local/lib/python3.13/site-packages/fastapi/middleware/asyncexitstack.py", line 20, in __call__
    raise e
  File "/usr/local/lib/python3.13/site-packages/fastapi/middleware/asyncexitstack.py", line 17, in __call__
    await self.app(scope, receive, send)
  File "/usr/local/lib/python3.13/site-packages/starlette/routing.py", line 718, in __call__
    await route.handle(scope, receive, send)
  File "/usr/local/lib/python3.13/site-packages/starlette/routing.py", line 276, in handle
    await self.app(scope, receive, send)
  File "/usr/local/lib/python3.13/site-packages/starlette/routing.py", line 66, in app
    response = await func(request)
               ^^^^^^^^^^^^^^^^^^^
  File "/usr/local/lib/python3.13/site-packages/fastapi/routing.py", line 274, in app
    raw_response = await run_endpoint_function(
                   ^^^^^^^^^^^^^^^^^^^^^^^^^^^^
        dependant=dependant, values=values, is_coroutine=is_coroutine
        ^^^^^^^^^^^^^^^^^^^^^^^^^^^^^^^^^^^^^^^^^^^^^^^^^^^^^^^^^^^^^
    )
    ^
  File "/usr/local/lib/python3.13/site-packages/fastapi/routing.py", line 193, in run_endpoint_function
    return await run_in_threadpool(dependant.call, **values)
           ^^^^^^^^^^^^^^^^^^^^^^^^^^^^^^^^^^^^^^^^^^^^^^^^^
  File "/usr/local/lib/python3.13/site-packages/starlette/concurrency.py", line 41, in run_in_threadpool
    return await anyio.to_thread.run_sync(func, *args)
           ^^^^^^^^^^^^^^^^^^^^^^^^^^^^^^^^^^^^^^^^^^^
  File "/usr/local/lib/python3.13/site-packages/anyio/to_thread.py", line 33, in run_sync
    return await get_asynclib().run_sync_in_worker_thread(
           ^^^^^^^^^^^^^^^^^^^^^^^^^^^^^^^^^^^^^^^^^^^^^^^
        func, *args, cancellable=cancellable, limiter=limiter
        ^^^^^^^^^^^^^^^^^^^^^^^^^^^^^^^^^^^^^^^^^^^^^^^^^^^^^
    )
    ^
  File "/usr/local/lib/python3.13/site-packages/anyio/_backends/_asyncio.py", line 877, in run_sync_in_worker_thread
    return await future
           ^^^^^^^^^^^^
  File "/usr/local/lib/python3.13/site-packages/anyio/_backends/_asyncio.py", line 807, in run
    result = context.run(func, *args)
  File "/home/workspace/main.py", line 76, in seed
    ngo_ids.append(db["ngo"].insert_one(NGO(name="Aranya Eco Foundation", registration_id="KA-REG-001", category="Air", city="Bengaluru", state="Karnataka", verified=True).model_dump()).inserted_id)
                   ~~~~~~~~~~~~~~~~~~~~^^^^^^^^^^^^^^^^^^^^^^^^^^^^^^^^^^^^^^^^^^^^^^^^^^^^^^^^^^^^^^^^^^^^^^^^^^^^^^^^^^^^^^^^^^^^^^^^^^^^^^^^^^^^^^^^^^^^^^^^^^^^^^^^^^^^^^^^^^^^^^^^^^
  File "/usr/local/lib/python3.13/site-packages/pymongo/collection.py", line 669, in insert_one
    self._insert_one(
    ~~~~~~~~~~~~~~~~^
        document,
        ^^^^^^^^^
    ...<5 lines>...
        comment=comment,
        ^^^^^^^^^^^^^^^^
    ),
    ^
  File "/usr/local/lib/python3.13/site-packages/pymongo/collection.py", line 609, in _insert_one
    self.__database.client._retryable_write(acknowledged, _insert_command, session)
    ~~~~~~~~~~~~~~~~~~~~~~~~~~~~~~~~~~~~~~~^^^^^^^^^^^^^^^^^^^^^^^^^^^^^^^^^^^^^^^^
  File "/usr/local/lib/python3.13/site-packages/pymongo/mongo_client.py", line 1523, in _retryable_write
    return self._retry_with_session(retryable, func, s, bulk)
           ~~~~~~~~~~~~~~~~~~~~~~~~^^^^^^^^^^^^^^^^^^^^^^^^^^
  File "/usr/local/lib/python3.13/site-packages/pymongo/mongo_client.py", line 1421, in _retry_with_session
    return self._retry_internal(
           ~~~~~~~~~~~~~~~~~~~~^
        func=func,
        ^^^^^^^^^^
    ...<2 lines>...
        retryable=retryable,
        ^^^^^^^^^^^^^^^^^^^^
    )
    ^
  File "/usr/local/lib/python3.13/site-packages/pymongo/_csot.py", line 107, in csot_wrapper
    return func(self, *args, **kwargs)
  File "/usr/local/lib/python3.13/site-packages/pymongo/mongo_client.py", line 1462, in _retry_internal
    ).run()
      ~~~^^
  File "/usr/local/lib/python3.13/site-packages/pymongo/mongo_client.py", line 2315, in run
    return self._read() if self._is_read else self._write()
                                              ~~~~~~~~~~~^^
  File "/usr/local/lib/python3.13/site-packages/pymongo/mongo_client.py", line 2422, in _write
    return self._func(self._session, conn, self._retryable)  # type: ignore
           ~~~~~~~~~~^^^^^^^^^^^^^^^^^^^^^^^^^^^^^^^^^^^^^^
  File "/usr/local/lib/python3.13/site-packages/pymongo/collection.py", line 597, in _insert_command
    result = conn.command(
        self.__database.name,
    ...<5 lines>...
        retryable_write=retryable_write,
    )
  File "/usr/local/lib/python3.13/site-packages/pymongo/helpers.py", line 322, in inner
    return func(*args, **kwargs)
  File "/usr/local/lib/python3.13/site-packages/pymongo/pool.py", line 968, in command
    return command(
        self,
    ...<20 lines>...
        write_concern=write_concern,
    )
  File "/usr/local/lib/python3.13/site-packages/pymongo/network.py", line 192, in command
    helpers._check_command_response(
    ~~~~~~~~~~~~~~~~~~~~~~~~~~~~~~~^
        response_doc,
        ^^^^^^^^^^^^^
    ...<2 lines>...
        parse_write_concern_error=parse_write_concern_error,
        ^^^^^^^^^^^^^^^^^^^^^^^^^^^^^^^^^^^^^^^^^^^^^^^^^^^^
    )
    ^
  File "/usr/local/lib/python3.13/site-packages/pymongo/helpers.py", line 230, in _check_command_response
    raise OperationFailure(errmsg, code, response, max_wire_version)
pymongo.errors.OperationFailure: Error=13, Details='Response status code does not indicate success: Forbidden (403); Substatus: 3090; ActivityId: 407c9a1d-d012-4b70-9e1a-744985e91c8d; Reason: ({"code":"Forbidden","message":"Message: {\"Errors\":[\"Database / Collection Count Quota exceeded: Maximum number of 'Collection' per account exceeded. Current configured quota 500. Learn more https://aka.ms/cosmosdbquota\"]}\r\nActivityId: 407c9a1d-d012-4b70-9e1a-744985e91c8d, Request URI: /apps/fc754a62-8507-4892-949e-99f2106b4b43/services/80fca9d2-512e-449c-bc04-bdeb0dc25d79/partitions/636e5357-71c4-4640-827f-1029b8907e57/replicas/133983777128881666p, RequestStats: , SDK: Microsoft.Azure.Documents.Common/2.14.0"}
RequestUri: https://developer-platform-user-db-5-uksouth.documents.azure.com/dbs/project_prj_qc0lcs45/colls;
RequestMethod: POST;
Header: Authorization Length: 82;
Header: x-ms-date Length: 29;
Header: x-ms-cosmos-sdk-supportedcapabilities Length: 1;
Header: x-ms-cosmos-insert-systempartitionkey Length: 4;
Header: x-ms-activity-id Length: 36;
Header: Cache-Control Length: 8;
Header: User-Agent Length: 145;
Header: x-ms-cosmos-apitype Length: 7;
Header: x-ms-version Length: 10;
Header: Accept Length: 16;
Header: x-ms-cosmos-compute-hop-count Length: 1;
Header: x-ms-gateway-use-mtls Length: 1;
Header: traceparent Length: 55;
Header: tracestate Length: 6;
, Request URI: /dbs/project_prj_qc0lcs45/colls, RequestStats: Microsoft.Azure.Cosmos.Tracing.TraceData.ClientSideRequestStatisticsTraceDatum, SDK: Windows/10.0.20348 cosmos-netstandard-sdk/3.18.0);, full error: {'ok': 0.0, 'errmsg': 'Error=13, Details=\'Response status code does not indicate success: Forbidden (403); Substatus: 3090; ActivityId: 407c9a1d-d012-4b70-9e1a-744985e91c8d; Reason: ({"code":"Forbidden","message":"Message: {\\"Errors\\":[\\"Database / Collection Count Quota exceeded: Maximum number of \'Collection\' per account exceeded. Current configured quota 500. Learn more https://aka.ms/cosmosdbquota\\"]}\\r\\nActivityId: 407c9a1d-d012-4b70-9e1a-744985e91c8d, Request URI: /apps/fc754a62-8507-4892-949e-99f2106b4b43/services/80fca9d2-512e-449c-bc04-bdeb0dc25d79/partitions/636e5357-71c4-4640-827f-1029b8907e57/replicas/133983777128881666p, RequestStats: , SDK: Microsoft.Azure.Documents.Common/2.14.0"}\r\nRequestUri: https://developer-platform-user-db-5-uksouth.documents.azure.com/dbs/project_prj_qc0lcs45/colls;\r\nRequestMethod: POST;\r\nHeader: Authorization Length: 82;\r\nHeader: x-ms-date Length: 29;\r\nHeader: x-ms-cosmos-sdk-supportedcapabilities Length: 1;\r\nHeader: x-ms-cosmos-insert-systempartitionkey Length: 4;\r\nHeader: x-ms-activity-id Length: 36;\r\nHeader: Cache-Control Length: 8;\r\nHeader: User-Agent Length: 145;\r\nHeader: x-ms-cosmos-apitype Length: 7;\r\nHeader: x-ms-version Length: 10;\r\nHeader: Accept Length: 16;\r\nHeader: x-ms-cosmos-compute-hop-count Length: 1;\r\nHeader: x-ms-gateway-use-mtls Length: 1;\r\nHeader: traceparent Length: 55;\r\nHeader: tracestate Length: 6;\r\n, Request URI: /dbs/project_prj_qc0lcs45/colls, RequestStats: Microsoft.Azure.Cosmos.Tracing.TraceData.ClientSideRequestStatisticsTraceDatum, SDK: Windows/10.0.20348 cosmos-netstandard-sdk/3.18.0);', 'code': 13, 'codeName': 'Unauthorized'}
INFO:     172.20.0.1:54392 - "GET /api/campaigns HTTP/1.1" 200 OK
INFO:     172.20.0.1:54378 - "GET /api/transactions HTTP/1.1" 200 OK
